Workbook

Sheet REVENUE
A1: REVENUE ASSURANCE REPORT FOR APRIL 2024
A3: DATE | B3: CARD | C3: SURCHARGE | D3: SURGERY | E3: LAB | F3: BED | G3: DRUGS | H3: DELIVERY | I3: MENTAL | J3: WATER | K3: P. REPORT | L3: DRESSING | M3: TOTAL
A4: 45295 | B4: =1300+1300 -> 2600 | G4: =7500+5000+8200+1000+20000+22600 -> 64300 | M4: =B4+C4+D4+E4+F4+G4+H4+I4+J4+K4+L4 -> 66900
A5: 45326 | B5: =1300+1300+2600+1500+1500+1500+1500+3500 -> 14700 | E5: =1000+9000 -> 10000 | G5: =8500+6000+2500+7200+4000+7100+9500+4500+5000+13200 -> 67500 | L5: 1000 | M5: =B5+C5+D5+E5+F5+G5+H5+I5+J5+K5+L5 -> 93200
A6: 45355 | B6: =1500+1500+1300+2600 -> 6900 | E6: =5000 -> 5000 | F6: =10000 -> 10000 | G6: =40000+10000+11500+4700+6000 -> 72200 | M6: =B6+C6+D6+E6+F6+G6+H6+I6+J6+K6+L6 -> 94100
A7: 45386 | B7: =1300+1300+2600+2600+1500 -> 9300 | E7: =1000+6500+1000 -> 8500 | G7: =2000+500+6500+8500+3200+15400+3000+12000+19000+2000+5000+10000+7200+10000 -> 104300 | M7: =B7+C7+D7+E7+F7+G7+H7+I7+J7+K7+L7 -> 122100
A8: 45416 | B8: =1500+1500+1500+1500+3500 -> 9500 | E8: =5000+1000+3500 -> 9500 | G8: =20000+4400+10000+5000+18500+17500+2000 -> 77400 | L8: 1000 | M8: =B8+C8+D8+E8+F8+G8+H8+I8+J8+K8+L8 -> 97400
A9: 45447 | B9: =1500+1500+1500+1500+1500+1500+1500 -> 10500 | E9: =5000 -> 5000 | G9: =3700+5300+4200+1000+2000+1500+3000 -> 20700 | K9: =3000 -> 3000 | M9: =B9+C9+D9+E9+F9+G9+H9+I9+J9+K9+L9 -> 39200
A10: 45477 | B10: =1500 -> 1500 | E10: =1000 -> 1000 | F10: =10000 -> 10000 | G10: =20000+1000+16500+23000+2500 -> 63000 | M10: =B10+C10+D10+E10+F10+G10+H10+I10+J10+K10+L10 -> 75500
A11: 45508 | B11: =1300+1300+1300 -> 3900 | E11: =19000 -> 19000 | G11: =7200+4000+3200+4000+30000+10000+4000+4500 -> 66900 | M11: =B11+C11+D11+E11+F11+G11+H11+I11+J11+K11+L11 -> 89800
A12: 45539 | B12: =1300+2600+1500 -> 5400 | E12: =4000 -> 4000 | F12: =10000 -> 10000 | G12: =8500+1000+2500+3000+5000+6550+50000+16000+12000 -> 104550 | H12: 15000 | M12: =B12+C12+D12+E12+F12+G12+H12+I12+J12+K12+L12 -> 138950
A13: 45569 | B13: =1300+1300+3000 -> 5600 | E13: =9500 -> 9500 | F13: =10000 -> 10000 | G13: =10000+1800+50000 -> 61800 | L13: =1000 -> 1000 | M13: =B13+C13+D13+E13+F13+G13+H13+I13+J13+K13+L13 -> 87900
A14: 45600 | B14: =1300+1300+2600 -> 5200 | E14: =4500+3000+2500 -> 10000 | G14: =8100+23500+7000+15300+11700+3000 -> 68600 | M14: =B14+C14+D14+E14+F14+G14+H14+I14+J14+K14+L14 -> 83800
A15: 45630 | B15: =1500+1500 -> 3000 | G15: =2500+15000+2000+17000 -> 36500 | L15: =2000 -> 2000 | M15: =B15+C15+D15+E15+F15+G15+H15+I15+J15+K15+L15 -> 41500
A16: 13/4/2024 | B16: =1500+1500+3000+6000+1500+1500 -> 15000 | G16: =9000+10000+10500+9250+4200+2000 -> 44950 | M16: =B16+C16+D16+E16+F16+G16+H16+I16+J16+K16+L16 -> 59950
A17: 14/4/2024 | B17: =1500+1500 -> 3000 | G17: =2850+13200+33600+15450+9200 -> 74300 | L17: 1000 | M17: =B17+C17+D17+E17+F17+G17+H17+I17+J17+K17+L17 -> 78300
A18: 15/5/2024 | B18: =1300+1300+1300 -> 3900 | G18: =4700+11100 -> 15800 | M18: =B18+C18+D18+E18+F18+G18+H18+I18+J18+K18+L18 -> 19700
A19: 16/5/2024 | B19: =1300+3000+3000 -> 7300 | E19: 5000 | G19: =700+10000 -> 10700 | L19: 1000 | M19: =B19+C19+D19+E19+F19+G19+H19+I19+J19+K19+L19 -> 24000
A20: 17/5/2024 | G20: =2700+2000 -> 4700 | L20: =1000 -> 1000 | M20: =B20+C20+D20+E20+F20+G20+H20+I20+J20+K20+L20 -> 5700
A21: 18/5/2024 | B21: =1300+1300+1300+1500+1500 -> 6900 | E21: 15000 | G21: =4200+4800+7500+7800+2000+200+4500+2500 -> 33500 | M21: =B21+C21+D21+E21+F21+G21+H21+I21+J21+K21+L21 -> 55400
A22: 19/5/2024 | B22: =1300+3000 -> 4300 | G22: =31400+16000+5200+1000+8300+22000+10000 -> 93900 | H22: 27000 | M22: =B22+C22+D22+E22+F22+G22+H22+I22+J22+K22+L22 -> 125200
A23: 20/5/2024 | B23: =1500+1500 -> 3000 | F23: =10000 -> 10000 | G23: =54600+12000+4500+5000+3200+2000+18500 -> 99800 | M23: =B23+C23+D23+E23+F23+G23+H23+I23+J23+K23+L23 -> 112800
A24: 21/5/2024 | B24: =1500 -> 1500 | M24: =B24+C24+D24+E24+F24+G24+H24+I24+J24+K24+L24 -> 1500
A25: 22/5/2024 | B25: =1300+1300+1500+3500 -> 7600 | G25: =4300+1500+1000+4200+700 -> 11700 | M25: =B25+C25+D25+E25+F25+G25+H25+I25+J25+K25+L25 -> 19300
A26: 23/4/2024 | B26: =3000+1500 -> 4500 | E26: =10500 -> 10500 | F26: =10000 -> 10000 | G26: =70600+4000+500+3300+6200+4200+500 -> 89300 | M26: =B26+C26+D26+E26+F26+G26+H26+I26+J26+K26+L26 -> 114300
A27: 24/4/2024 | B27: =1500+1300 -> 2800 | E27: =5000 -> 5000 | G27: =20000+18800 -> 38800 | M27: =B27+C27+D27+E27+F27+G27+H27+I27+J27+K27+L27 -> 46600
A28: 25/4/2024 | B28: =1300+1300 -> 2600 | E28: =6500 -> 6500 | G28: =29200 -> 29200 | L28: =1000 -> 1000 | M28: =B28+C28+D28+E28+F28+G28+H28+I28+J28+K28+L28 -> 39300
A29: 26/4/2024 | B29: =1300+1500+1500 -> 4300 | F29: =6000 -> 6000 | G29: =40400+10000+10000+1000 -> 61400 | I29: =33500 -> 33500 | M29: =B29+C29+D29+E29+F29+G29+H29+I29+J29+K29+L29 -> 105200
A30: 27/4/2024 | B30: =1500+1500+1500+1500+1500+3000 -> 10500 | G30: =16000+5000+6000+15000+21000+10000+3000+19200 -> 95200 | M30: =B30+C30+D30+E30+F30+G30+H30+I30+J30+K30+L30 -> 105700
A31: 28/4/2024 | B31: =1500+1500 -> 3000 | G31: =3500+5200+4000 -> 12700 | M31: =B31+C31+D31+E31+F31+G31+H31+I31+J31+K31+L31 -> 15700
A32: 29/4/2024 | B32: =2600+1300+1300+3000 -> 8200 | E32: =20000+13000+7000+5500 -> 45500 | G32: =4500+5300+3200+500+3200+2900+4000+1000+8300+500+6900+2800 -> 43100 | M32: =B32+C32+D32+E32+F32+G32+H32+I32+J32+K32+L32 -> 96800
A33: 30/4/2024 | B33: =1500+1500+1300 -> 4300 | E33: =6500 -> 6500 | G33: =3000+20000+8300+1700 -> 33000 | L33: =1000 -> 1000 | M33: =B33+C33+D33+E33+F33+G33+H33+I33+J33+K33+L33 -> 44800
M34: =B34+C34+D34+E34+F34+G34+H34+I34+J34+K34+L34 -> 0
B35: =SUM(B4:B34) -> 170800 | C35: =SUM(C4:C34) -> 0 | D35: =SUM(D4:D34) -> 0 | E35: =SUM(E4:E34) -> 175500 | F35: =SUM(F4:F34) -> 66000 | G35: =SUM(G4:G34) -> 1599800 | H35: =SUM(H4:H34) -> 42000 | I35: =SUM(I4:I34) -> 33500 | ... M35: =SUM(M4:M34) -> 2100600
D37: %
B38: CARD | D38: =B35/M35*100 -> 8.1310102
B39: SURCHARGE | D39: =C35/M35*100 -> 0
B40: SURGERY | D40: =D35/M35*100 -> 0 | H40: N
B41: =E3 -> LAB | D41: =E35/M35*100 -> 8.3547558
B42: BED | D42: =F35/M35*100 -> 3.1419594 | G42: SALES | H42: =E35+G35+H35+I35+L35+J35 -> 1860800
...

Sheet EXPENSES
A1: DATE | B1: PARTICULARS | D1: Invoice No. | E1: AMOUNT
A2: 45508 | B2: FUEL | E2: 38000
A3: 45386 | B3: ENGINE OIL | E3: 12000
A4: 45508 | B4: STORE PURCHASE:MEDICINE | E4: 10000
A5: 45477 | B5: WEED CONTROL | E5: 5000
A6: 45508 | B6: STORE PURCHASE: MEDICINE | C6: ELBE PHARMA NIG LTD | E6: 400000 | F6: 538500
A7: 14/4/2024 | B7: STORE PURCHASE: MEDICINE | C7: RICHARD MED | E7: 20250
A8: 14/4/2024 | B8: STORE PURCHASE: MEDICINE | C8: ELBE PHARMA NIG LTD | D8: 745 | E8: 25000
A9: 16/4/2024 | B9: OFFICE SUPPLY:6 MOP STICK @ N1000, 1CTN OF OMO @ N7000, 1CTN OF HYPO @ N7,700 | E9: 20700
A10: 16/4/2024 | B10: STORE PURCHASE: SYRINGS &NEEDLE | E10: 43000
A11: 16/4/2024 | B11: TRANSPORT FOR PURCHASE | E11: 2000
A12: 16/4/2024 | B12: 2 PCS OF 25 LTRS @ N4000 | E12: 8000
A13: 18/4/2024 | B13: TRANSPORT FOR DISTILLED WATER | E13: 9000
A14: 18/4/2024 | B14: STORE PURCHASE: MEDICINE | C14: ELBE PHARMA NIG LTD | D14: 745 | E14: 6000
A15: 18/4/2024 | B15: STORE PURCHASE: MEDICINE | C15: EKWUEME | E15: 151000
A16: 18/4/2024 | B16: TRANSPORT FOR PURCHASE | E16: 5000
A17: 25/4/2024 | B17: STORE PURCHASE: MEDICINE | C17: DE BLESSED MEKUS | D17: 2453 | E17: 151300
A18: 25/4/2024 | B18: STORE PURCHASE: MEDICINE | C18: SUCCESSLINK SURGICAL | D18: 3148 | E18: 264500
A19: 18/4/2024 | B19: OFFICE SUPPLY: TOUCH 7000,PEN 700,TICKNOTE @ N3000. | E19: 10700
A20: 18/4/2024 | B20: TRANSPORT | E20: 12700
A21: 25/4/2024 | B21: STORE PURCHASE: MEDICINE | E21: 31500
A22: 25/4/2024 | B22: FUEL | E22: 40500
A23: 25/4/2024 | B23: REPAIR OF LOCKS | E23: 13500
A24: 25/4/2024 | B24: DEPOSIT FOR PRODUCTION OF FOLDERS | E24: 50000
A25: 25/4/2024
A26: 25/4/2024
A27: 25/4/2024
A28: 25/4/2024
A29: 25/4/2024
A30: 25/4/2024
A31: 25/4/2024
A32: 25/4/2024
A33: 25/4/2024
A34: 25/4/2024
A35: 45020
E38: =SUM(E2:E37) -> 1329650

Sheet FIN. REPORT
A2: STATEMENT OF FINANCIAL PERFORMANCE FOR THE MONTH ENDED 30/04/2024
B3: N | C3: N
A4: REVENUE (CASH) | C4: =[1]REVENUE!M35 -> 2100600
A5: Stock @ 1/04/2024 | B5: 2424855
A6: Add PURCHASES | B6: =[1]MEDICATIONS!E12 -> 1102550
A7: Add Carriage | B7: =[1]MEDICATIONS!E18 -> 19700
A8: Less STOCK AS AT 30/04/2024 | B8: 2975185
A9: COST OF SALES | C9: =B5+B6+B7-B8 -> 571920
A10: GROSS PROFIT | C10: =C4-C9 -> 1528680 | I10: =589000+2700000 -> 3289000
A11: EXPENSES
A12: SALARIES | B12: =150000+1065000 -> 1215000
A13: OFFICE SUPPLIES | B13: ='[1]MAINTENANCE-OFFICE SUPPLIES'!E13 -> 116900
A14: POWER/LIGHTING | B14: ='[1]MAINTENANCE-OFFICE SUPPLIES'!E22 -> 90500
A15: WAGES
A16: TRANSPORT | C16: =B12+B13+B14+B15+B16 -> 1422400
A17: NET PROFIT/LOSS | C17: =C10-C16 -> 106280
A21: INDEGENT | C21: 88400
A22: DEMENTIA | C22: 6200
A23: BLOOMS
A24: PSYCHIATRICS | C24: 66000
C25: =C21+C22+C23+C24 -> 160600
A26: ACTUAL NET PROFIT | C26: =C17+C25 -> 266880

Sheet MAINTENANCE-OFFICE SUPPLIES
A1: DATE | B1: PARTICULARS | D1: Invoice No. | E1: AMOUNT
A2: 45477 | B2: WEED CONTROL | E2: 5000
A3: 16/4/2024 | B3: OFFICE SUPPLY:6 MOP STICK @ N1000, 1CTN OF OMO @ N7000, 1CTN OF HYPO @ N7,700 | E3: 20700
A4: 16/4/2024 | B4: 2 PCS OF 25 LTRS @ N4000 | E4: 8000
A5: 18/4/2024 | B5: OFFICE SUPPLY: TOUCH 7000,PEN 700,TICKNOTE @ N3000. | E5: 10700
A6: 18/4/2024 | B6: TRANSPORT FOR DISTILLED WATER | E6: 9000
A7: 25/4/2024 | B7: REPAIR OF LOCKS | E7: 13500
A8: 25/4/2024 | B8: DEPOSIT FOR PRODUCTION OF FOLDERS | E8: 50000
B13: TOTAL | E13: =SUM(E2:E12) -> 116900
A18: 45508 | B18: FUEL | E18: 38000
A19: 45386 | B19: ENGINE OIL | E19: 12000
A20: 25/4/2024 | B20: FUEL | E20: 40500
E22: =SUM(E18:E21) -> 90500

Sheet MEDICATIONS
A1: 45508 | B1: STORE PURCHASE:MEDICINE | E1: 10000
A2: 45508 | B2: STORE PURCHASE: MEDICINE | C2: ELBE PHARMA NIG LTD | E2: 400000 | F2: 538500
A3: 14/4/2024 | B3: STORE PURCHASE: MEDICINE | C3: RICHARD MED | E3: 20250
A4: 14/4/2024 | B4: STORE PURCHASE: MEDICINE | C4: ELBE PHARMA NIG LTD | D4: 745 | E4: 25000
A5: 16/4/2024 | B5: STORE PURCHASE: SYRINGS &NEEDLE | E5: 43000
A6: 18/4/2024 | B6: STORE PURCHASE: MEDICINE | C6: ELBE PHARMA NIG LTD | D6: 745 | E6: 6000
A7: 18/4/2024 | B7: STORE PURCHASE: MEDICINE | C7: EKWUEME | E7: 151000
A8: 25/4/2024 | B8: STORE PURCHASE: MEDICINE | C8: DE BLESSED MEKUS | D8: 2453 | E8: 151300
A9: 25/4/2024 | B9: STORE PURCHASE: MEDICINE | C9: SUCCESSLINK SURGICAL | D9: 3148 | E9: 264500
A10: 25/4/2024 | B10: STORE PURCHASE: MEDICINE | E10: 31500
E12: =SUM(E1:E11) -> 1102550
A15: 16/4/2024 | B15: TRANSPORT FOR PURCHASE | E15: 2000
A16: 18/4/2024 | B16: TRANSPORT | E16: 12700
A17: 18/4/2024 | B17: TRANSPORT FOR PURCHASE | E17: 5000
E18: =SUM(E15:E17) -> 19700

Sheet SUMMARY
A2: SUMMARY
B3: DEPOSITE INTO ACIU ACOUNT | F3: =REVENUE!H52 -> 864450
B4: EXPENSES | F4: =REVENUE!H53 -> 1329650
B5: TOTAL | F5: =F3+F4 -> 2194100
B6: BAL B/D | F6: =REVENUE!H55 -> 67845
B7: GRAND TOTAL | F7: =F5+F6 -> 2261945
A10: TOTAL CASH FOR THE MONTH OF APRIL, 2024
B12: TOTAL AMOUNT | F12: =REVENUE!M35 -> 2100600
B13: BAL. B/F | F13: =REVENUE!H46 -> 161345
B14: TOTAL | F14: =F12+F13 -> 2261945
A17: OTHER POINTS TO NOTE
A18: WE STILL HAVE STOCK (MEDICATION) VALUED N2,975,185 AT COST PRICE.
A19: CASH RECEIVED IS N1,236,150
A20: CASH TRANSFERS N864,450
A21: CASH EARNED THROUGH INDEGENT,DELIVERY SUBSIDY, DEMENTIA AND BLOOM SCHOLARS N160,600
A22: WE OWE A DEBT OF N73,500

Sheet EZINNE LAB
A2: STATEMENT OF FINANCIAL PERFORMANCE FOR THE MONTH ENDED 30/04/2024
B3: N | C3: N
A4: REVENUE (CASH) | C4: =REVENUE!E35 -> 175500
A5: Stock @ 1/3/2024 | B5: 282000 | G5: AMOUNT IN SEPTEMBER | H5: 249000
A6: Add PURCHASES | B6: 61500 | G6: AMOUNT IN OCTOBER | H6: 280000
A7: Add Carriage | G7: OPENING STOCK OF SEPT | H7: 76010
A8: Less STOCK AS AT 31/3/2024 | B8: 291000 | G8: TOTAL INVESTMENT | H8: =SUM(H5:H7) -> 605010
A9: COST OF SALES | C9: =B5+B6+B7-B8 -> 52500
A10: GROSS PROFIT | C10: =C4-C9 -> 123000 | G10: REVENUE FOR SEPT | I10: 337500
A11: EXPENSES | G11: REVENUE FOR OCT | I11: 261500
A12: SALARIES | B12: 35000 | G12: TOTAL REVENUE | I12: =SUM(I10:I11) -> 599000
A13: OFFICE SUPPLIES | B13: 24000
A14: POWER/LIGHTING | B14: 22600 | G14: SALARY FOR SEPT/OCT | H14: 210000
A15: WAGES | G15: TOTAL INVESTMENT& SALARY | H15: =SUM(H8:H14) -> 815010
A16: TRANSPORT | C16: =B12+B13+B14+B15+B16 -> 81600
A17: NET PROFIT/LOSS | C17: =C10-C16 -> 41400 | G17: LESS TOTAL REVENUE | H17: 599000
G18: BALANCE | H18: =H15-H17 -> 216010
A21: INDEGENT
A22: DEMENTIA
A23: BLOOMS SCHOLARS | G23: MAR. BALANCE | H23: 314110
A24: PSYCHIATRICS | G24: LESS APRIL. PROFIT | H24: 41400
C25: =C21+C22+C23+C24 -> 0 | H25: =H23-H24 -> 272710
A26: ACTUAL NET PROFIT | C26: =C17+C25 -> 41400
