Workbook

Sheet REVENUE
A1: REVENUE ASSURANCE REPORT FOR AUGUST 2025
A3: DATE | B3: CARD | C3: SURCHARGE | D3: SURGERY | E3: LAB | F3: BED | G3: DRUGS | H3: DELIVERY | I3: MENTAL | J3: WATER | K3: P. REPORT | L3: DRESSING | M3: TOTAL
A4: 45665 | G4: =28700+44000+11000+3000+15000+35000+20000+34000 -> 190700 | M4: =B4+C4+D4+E4+F4+G4+H4+I4+J4+K4+L4 -> 190700
A5: 45696 | G5: =12200+17200+10000+18500+11500+9700+21200+2000+1000 -> 103300 | M5: =B5+C5+D5+E5+F5+G5+H5+I5+J5+K5+L5 -> 103300
A6: 45724 | G6: =3000+5200+21200 -> 29400 | L6: =2000 -> 2000 | M6: =B6+C6+D6+E6+F6+G6+H6+I6+J6+K6+L6 -> 31400
A7: 45755 | E7: =2000 -> 2000 | G7: =2800 -> 2800 | M7: =B7+C7+D7+E7+F7+G7+H7+I7+J7+K7+L7 -> 4800
A8: 45785 | E8: =7000+8000 -> 15000 | G8: =28000+6500+5500+4500 -> 44500 | M8: =B8+C8+D8+E8+F8+G8+H8+I8+J8+K8+L8 -> 59500
A9: 45816 | G9: =18000+10600 -> 28600 | L9: =15000 -> 15000 | M9: =B9+C9+D9+E9+F9+G9+H9+I9+J9+K9+L9 -> 43600
A10: 45846 | E10: =9000+2000+2000+10000 -> 23000 | G10: =16200+2500+12000+81800+19200 -> 131700 | M10: =B10+C10+D10+E10+F10+G10+H10+I10+J10+K10+L10 -> 154700
A11: 45877 | G11: =18500+27000+20000+6000+11200+10000+10000+6200+8500+10000 -> 127400 | M11: =B11+C11+D11+E11+F11+G11+H11+I11+J11+K11+L11 -> 127400
A12: 45908 | G12: =7000+1000+18400+3000 -> 29400 | M12: =B12+C12+D12+E12+F12+G12+H12+I12+J12+K12+L12 -> 29400
A13: 45938 | G13: =44000+1000+82500+5000+10000+5000+5200 -> 152700 | M13: =B13+C13+D13+E13+F13+G13+H13+I13+J13+K13+L13 -> 152700
A14: 45969 | G14: =17700+9000+5000+29000+5500+3000 -> 69200 | M14: =B14+C14+D14+E14+F14+G14+H14+I14+J14+K14+L14 -> 69200
A15: 45999 | G15: =4000+9300+5000+5000+6000+27000+21450+22200+20000+18500+13000+7000 -> 158450 | M15: =B15+C15+D15+E15+F15+G15+H15+I15+J15+K15+L15 -> 158450
A16: 13/8/2025 | G16: =8000+1000+15200+200000+200000+38000 -> 462200 | M16: =B16+C16+D16+E16+F16+G16+H16+I16+J16+K16+L16 -> 462200
A17: 14/8/2025 | E17: =11000+10000+8000+10000 -> 39000 | G17: =2000+3500+7000+8000+24000+11000+4000 -> 59500 | M17: =B17+C17+D17+E17+F17+G17+H17+I17+J17+K17+L17 -> 98500
A18: 15/8/2025 | E18: =10000 -> 10000 | G18: =7500+13000+28300+10000+18000 -> 76800 | M18: =B18+C18+D18+E18+F18+G18+H18+I18+J18+K18+L18 -> 86800
A19: 16/8/2025 | G19: =11200+4500 -> 15700 | M19: =B19+C19+D19+E19+F19+G19+H19+I19+J19+K19+L19 -> 15700
A20: 17/8/2025 | G20: =15000+15000+34250 -> 64250 | M20: =B20+C20+D20+E20+F20+G20+H20+I20+J20+K20+L20 -> 64250
A21: 18/8/2025 | E21: =18000 -> 18000 | G21: =3800+5000+2000+10000+800 -> 21600 | M21: =B21+C21+D21+E21+F21+G21+H21+I21+J21+K21+L21 -> 39600
A22: 19/8/2025 | G22: =2800+1000+6000+12000+33200+2500+19300 -> 76800 | M22: =B22+C22+D22+E22+F22+G22+H22+I22+J22+K22+L22 -> 76800
A23: 20/8/2025 | E23: =10000 -> 10000 | G23: =14200+3000+10000+31000+5000 -> 63200 | M23: =B23+C23+D23+E23+F23+G23+H23+I23+J23+K23+L23 -> 73200
A24: 21/8/2025 | E24: =1000+7000+9000+5000 -> 22000 | G24: =7600+7500+39200+20000+1000+5000+50000 -> 130300 | M24: =B24+C24+D24+E24+F24+G24+H24+I24+J24+K24+L24 -> 152300
A25: 22/8/2025 | E25: =10000+4000 -> 14000 | G25: =21300+18000+10500+18600+5000 -> 73400 | M25: =B25+C25+D25+E25+F25+G25+H25+I25+J25+K25+L25 -> 87400
A26: 23/8/2025 | G26: =10500+26300+1000 -> 37800 | M26: =B26+C26+D26+E26+F26+G26+H26+I26+J26+K26+L26 -> 37800 | Q26: =11000+44000+3000+28700+35000+20000+34000+17200+12200+21200+5200+28000+12000+10000+19200+11200+8500+20000+29000+27000+7000+44000+82500 -> 529900 | S26: =253550-102250 -> 151300 | T26: =S26-231530-70300 -> -150530
A27: 24/8/2025 | G27: =8000+4500+30000+13450 -> 55950 | M27: =B27+C27+D27+E27+F27+G27+H27+I27+J27+K27+L27 -> 55950 | Q27: =5200+5000+17700+3000+200000+200000+21450+22200+18500+13000+38000+10000+11000+11000+7000+16000+10000+3500 -> 612550 | S27: =470200-Q27 -> -142350 | T27: =S27+T26+24450 -> -268430
A28: 25/8/2025 | G28: =5000+4000+6000 -> 15000 | M28: =B28+C28+D28+E28+F28+G28+H28+I28+J28+K28+L28 -> 15000 | Q28: =24000+18000+13000+28300+11200+4500+15000+15000+18000+800+2000+19300+33200+10000+14200+50000+7000+9000+20000+21300 -> 333800 | S28: =546900-Q28 -> 213100 | T28: =S28+T27-166800 -> -222130
A29: 26/8/2025 | G29: =1200+5200+8000 -> 14400 | M29: =B29+C29+D29+E29+F29+G29+H29+I29+J29+K29+L29 -> 14400 | Q29: =18000+10500+26300+8000+10500+8000+50000+55000+4200+25000+20000+6000+10000+18400+37400+37000+16000+17000 -> 377300
A30: 27/8/2025 | G30: =1000+55000+7450+8500+5000+4000+17000+50000+4200+25000+20000 -> 197150 | M30: =B30+C30+D30+E30+F30+G30+H30+I30+J30+K30+L30 -> 197150
A31: 28/8/2025 | E31: =6000 -> 6000 | G31: =48400+10000+2000+10000+18200+10000 -> 98600 | I31: =32000 -> 32000 | M31: =B31+C31+D31+E31+F31+G31+H31+I31+J31+K31+L31 -> 136600 | Q31: =SUM(Q25:Q30) -> 1853550
A32: 29/8/2025 | G32: =1000+5000+18400 -> 24400 | M32: =B32+C32+D32+E32+F32+G32+H32+I32+J32+K32+L32 -> 24400
A33: 30/8/2025 | G33: =37400 -> 37400 | M33: =B33+C33+D33+E33+F33+G33+H33+I33+J33+K33+L33 -> 37400
A34: 31/8/2025 | E34: =1000 -> 1000 | G34: =16000+37000+17000+6000 -> 76000 | M34: =B34+C34+D34+E34+F34+G34+H34+I34+J34+K34+L34 -> 77000
B35: =SUM(B4:B34) -> 0 | C35: =SUM(C4:C34) -> 0 | D35: =SUM(D4:D34) -> 0 | E35: =SUM(E4:E34) -> 160000 | F35: =SUM(F4:F34) -> 0 | G35: =SUM(G4:G34) -> 2668600 | H35: =SUM(H4:H34) -> 0 | I35: =SUM(I4:I34) -> 32000 | ... M35: =SUM(M4:M34) -> 2877600
D37: % | P37: =M35-Q31 -> 1024050
B38: CARD | D38: =B35/M35*100 -> 0
B39: SURCHARGE | D39: =C35/M35*100 -> 0
B40: SURGERY | D40: =D35/M35*100 -> 0 | H40: N
B41: =E3 -> LAB | D41: =E35/M35*100 -> 5.560189
B42: BED | D42: =F35/M35*100 -> 0 | G42: SALES | H42: =E35+G35+H35+I35+L35+J35 -> 2877600
...

Sheet GEN.EXPENSES
A1: DATE | B1: PARTICULARS | D1: Invoice No. | E1: AMOUNT
A2: 45724 | B2: STORE PURCHASE:MEDICINE | C2: EKWUEME | E2: 304900
A3: 45816 | B3: STORE PURCHASE:MEDICINE | C3: GRACE & MERCY | E3: 53100
A4: 45816 | B4: STORE PURCHASE:MEDICINE (LOCAL) | E4: =3000+6000 -> 9000
A5: 45816 | B5: FUEL | E5: 56000
A6: 45816 | B6: STORE PURCHASE:MEDICINE (LOCAL) | E6: =2000+2500+8500+19000 -> 32000
A7: 15/8/2025 | B7: STORE PURCHASE:MEDICINE | E7: =22500+55000+38000+42000+18000+60000+44000+30000+39500+23800+12000 -> 384800
A8: 15/8/2025 | B8: CARRIAGE | E8: 19500
A9: 15/8/2025 | B9: STORE PURCHASE:MEDICINE | C9: SUCCSSLINK | D9: 1561 | E9: 57300
A10: 15/8/2025 | B10: STORE PURCHASE:MEDICINE | C10: SUCCSSLINK | D10: 1560 | E10: 174500
A11: 15/8/2025 | B11: STORE PURCHASE:MEDICINE | C11: BLESSED MEKUS | E11: 198850
A12: 16/8/2025 | B12: WAYBILL | E12: 3000
A13: 16/8/2025 | B13: HERBICIDES | E13: 5000
A14: 16/8/2025 | B14: ENCINE OIL | E14: 15000
A15: 16/8/2025 | B15: REFUND | E15: 10000
A16: 28/8/2025 | B16: STORE PURCHASE:MEDICINE | E16: =2000+1300 -> 3300
A17: 28/8/2025
A18: 28/8/2025
A19: 28/8/2025
A32: 22/9/2024
A33: 22/9/2024
A34: 22/9/2024
A35: 22/9/2024
E39: =SUM(E2:E38) -> 1326250

Sheet FIN. REPORT
A2: STATEMENT OF FINANCIAL PERFORMANCE FOR THE MONTH ENDED 31/08/2025
B3: N | C3: N
A4: REVENUE (CASH) | C4: =[1]REVENUE!M35 -> 2877600
A5: Stock @ 1/8/2025 | B5: 1550000
A6: Add PURCHASES | B6: =[1]MEDICATIONS!E18 -> 1217750
A7: Add Carriage | B7: =[1]MEDICATIONS!E24 -> 22500
A8: Less STOCK AS AT 31/8/2025 | B8: 1579450
A9: COST OF SALES | C9: =B5+B6+B7-B8 -> 1210800
A10: GROSS PROFIT | C10: =C4-C9 -> 1666800
A11: EXPENSES
A12: SALARIES | B12: =170000+1325000 -> 1495000
A13: OFFICE SUPPLIES | B13: ='[1]MAINTENANCE-OFFICE SUPPLIES'!E21 -> 30000
A14: POWER/LIGHTING | B14: ='[1]MAINTENANCE-OFFICE SUPPLIES'!E30 -> 56000
A15: WAGES
A16: TRANSPORT | C16: =B12+B13+B14+B15+B16 -> 1581000
A17: NET PROFIT/LOSS | C17: =C10-C16 -> 85800
A21: INDEGENT | C21: 128500
A22: DEMENTIA | C22: 9500
A23: BLOOMS
A24: PSYCHIATRICS | C24: 84000
C25: =C21+C22+C23+C24 -> 222000
A26: ACTUAL NET LOSS | C26: =C17+C25 -> 307800

Sheet MAINTENANCE-OFFICE SUPPLIES
A1: DATE | B1: PARTICULARS | D1: Invoice No. | E1: AMOUNT
A2: 16/8/2025 | B2: HERBICIDES | E2: 5000
A3: 16/8/2025 | B3: ENCINE OIL | E3: 15000
A4: 16/8/2025 | B4: REFUND | E4: 10000
B21: TOTAL | E21: =SUM(E2:E20) -> 30000
A26: 45816 | B26: FUEL | E26: 56000
B27: FUEL
E30: =SUM(E26:E29) -> 56000

Sheet MEDICATIONS
A1: 45724 | B1: STORE PURCHASE:MEDICINE | C1: EKWUEME | E1: 304900
A2: 45816 | B2: STORE PURCHASE:MEDICINE | C2: GRACE & MERCY | E2: 53100
A3: 45816 | B3: STORE PURCHASE:MEDICINE (LOCAL) | E3: =3000+6000 -> 9000
A4: 45816 | B4: STORE PURCHASE:MEDICINE (LOCAL) | E4: =2000+2500+8500+19000 -> 32000
A5: 15/8/2025 | B5: STORE PURCHASE:MEDICINE | E5: =22500+55000+38000+42000+18000+60000+44000+30000+39500+23800+12000 -> 384800
A6: 15/8/2025 | B6: STORE PURCHASE:MEDICINE | C6: SUCCSSLINK | D6: 1561 | E6: 57300
A7: 15/8/2025 | B7: STORE PURCHASE:MEDICINE | C7: SUCCSSLINK | D7: 1560 | E7: 174500
A8: 15/8/2025 | B8: STORE PURCHASE:MEDICINE | C8: BLESSED MEKUS | E8: 198850
A9: 28/8/2025 | B9: STORE PURCHASE:MEDICINE | E9: =2000+1300 -> 3300
E18: =SUM(E1:E17) -> 1217750
A21: 15/8/2025 | B21: CARRIAGE | E21: 19500
A22: 16/8/2025 | B22: WAYBILL | E22: 3000
E24: =SUM(E21:E23) -> 22500
E26: =E19+E24 -> 22500
C29: medi | D29: =E19 -> 0
C30: carriage | D30: =E24 -> 22500
D32: =D29+D30+D31 -> 22500

Sheet SUMMARY
A2: SUMMARY
B3: DEPOSITE INTO ACIU ACOUNT | F3: =REVENUE!H52 -> 1853550
B4: EXPENSES | F4: =REVENUE!H53 -> 1326250
B5: TOTAL | F5: =F3+F4 -> 3179800
B6: BAL B/D | F6: =REVENUE!J55 -> -2115
B7: GRAND TOTAL | F7: =F5+F6 -> 3177685
A10: TOTAL CASH FOR THE MONTH OF AUGUST 2025
B12: TOTAL AMOUNT | F12: =REVENUE!H47 -> 3177685
B13: BAL. B/F
B14: TOTAL | F14: =F12+F13 -> 3177685
A17: OTHER POINTS TO NOTE
A18: WE STILL HAVE STOCK (MEDICATION) VALUED N1,579,450 AT COST PRICE.
A19: CASH DEPOSIT IS N1,024,050
A20: CASH EARNED THROUGH INDEGENT,DELIVERY SUBSIDY, DEMENTIA AND BLOOM SCHOLARS N222,000
A21: TOTAT CASH IN BANK N1,853,550

Sheet LAB.
A2: STATEMENT OF FINANCIAL PERFORMANCE FOR THE MONTH ENDED 31/8/2025
B3: N | C3: N
A4: REVENUE (CASH) | C4: =REVENUE!E35 -> 160000
A5: Stock @ 1/8/2025 | B5: 210500
A6: Add PURCHASES | B6: 167000
A7: Add Carriage | B7: 5000
A8: Less STOCK AS AT 31/8/2025 | B8: 361000
A9: COST OF SALES | C9: =B5+B6+B7-B8 -> 21500
A10: GROSS PROFIT | C10: =C4-C9 -> 138500
A11: EXPENSES
A12: SALARIES | B12: 45000
A13: OFFICE SUPPLIES | B13: 3000
A14: POWER/LIGHTING | B14: =11780+18900 -> 30680
A15: WAGES
A16: TRANSPORT | C16: =B12+B13+B14+B15+B16 -> 78680
A17: NET PROFIT/LOSS | C17: =C10-C16 -> 59820
A21: INDEGENT | C21: 21500
A22: DEMENTIA
A23: BLOOMS SCHOLARS
A24: PSYCHIATRICS
C25: =C21+C22+C23+C24 -> 21500
A26: ACTUAL NET PROFIT | C26: =C17+C25 -> 81320
