Workbook

Sheet REVENUE
A1: REVENUE ASSURANCE REPORT FOR DECEMBER 2025
A3: DATE | B3: CARD | C3: SURCHARGE | D3: SURGERY | E3: LAB | F3: BED | G3: DRUGS | H3: DELIVERY | I3: MENTAL | J3: WATER | K3: P. REPORT | L3: DRESSING | M3: TOTAL
A4: 45669 | E4: =8000+3000+1000 -> 12000 | G4: =6000+2800+1000+15000 -> 24800 | M4: =B4+C4+D4+E4+F4+G4+H4+I4+J4+K4+L4 -> 36800
A5: 45700 | E5: =6000 -> 6000 | F5: =4000 -> 4000 | G5: =2200+53200+1800 -> 57200 | M5: =B5+C5+D5+E5+F5+G5+H5+I5+J5+K5+L5 -> 67200
A6: 45728 | E6: =4000+12000 -> 16000 | G6: =2000+3200+7200+6000 -> 18400 | M6: =B6+C6+D6+E6+F6+G6+H6+I6+J6+K6+L6 -> 34400
A7: 45759 | E7: =15000 -> 15000 | F7: =6000 -> 6000 | G7: =7200+9000+33200+3500+1000+6000+2500+3200+34800 -> 100400 | M7: =B7+C7+D7+E7+F7+G7+H7+I7+J7+K7+L7 -> 121400
A8: 45789 | G8: =1000+15000+30000+1000 -> 47000 | M8: =B8+C8+D8+E8+F8+G8+H8+I8+J8+K8+L8 -> 47000
A9: 45820 | F9: =4000 -> 4000 | G9: =31300+65000+21200 -> 117500 | M9: =B9+C9+D9+E9+F9+G9+H9+I9+J9+K9+L9 -> 121500
A10: 45850 | E10: =11000+5000 -> 16000 | G10: =3000+3200 -> 6200 | M10: =B10+C10+D10+E10+F10+G10+H10+I10+J10+K10+L10 -> 22200
A11: 45881 | E11: =1000+4000 -> 5000 | G11: =1500+15200+3000 -> 19700 | M11: =B11+C11+D11+E11+F11+G11+H11+I11+J11+K11+L11 -> 24700
A12: 45912 | E12: =2000+1000 -> 3000 | G12: =10000+8000+8500+7000+5500+29300+5200+3000 -> 76500 | M12: =B12+C12+D12+E12+F12+G12+H12+I12+J12+K12+L12 -> 79500
A13: 45942 | E13: =2000 -> 2000 | F13: =2000 -> 2000 | G13: =1000+3500+5500+13000+30000+4500+3000 -> 60500 | M13: =B13+C13+D13+E13+F13+G13+H13+I13+J13+K13+L13 -> 64500
A14: 45973 | G14: =5600+4700+15000 -> 25300 | M14: =B14+C14+D14+E14+F14+G14+H14+I14+J14+K14+L14 -> 25300
A15: 46003 | E15: =1000+1000 -> 2000 | G15: =20000+45000+20000+10000+1000+73000+9450+6500 -> 184950 | M15: =B15+C15+D15+E15+F15+G15+H15+I15+J15+K15+L15 -> 186950
A16: 13/12/2025 | E16: =1000+1000 -> 2000 | F16: =4000 -> 4000 | G16: =30000+5000+20000+55000 -> 110000 | M16: =B16+C16+D16+E16+F16+G16+H16+I16+J16+K16+L16 -> 116000 | P16: =19200+15000+19700 -> 53900
A17: 14/12/2025 | E17: =10000 -> 10000 | G17: =9300+30200 -> 39500 | M17: =B17+C17+D17+E17+F17+G17+H17+I17+J17+K17+L17 -> 49500
A18: 15/12/2025 | E18: =5000+1600 -> 6600 | G18: =9200+7000+8000+1000 -> 25200 | M18: =B18+C18+D18+E18+F18+G18+H18+I18+J18+K18+L18 -> 31800
A19: 16/12/2025 | E19: =2000+6000 -> 8000 | G19: =4200+12200+3800+26200+4500 -> 50900 | M19: =B19+C19+D19+E19+F19+G19+H19+I19+J19+K19+L19 -> 58900
A20: 17/12/2025 | E20: =2000 -> 2000 | G20: =9500+1000+2000+5000 -> 17500 | M20: =B20+C20+D20+E20+F20+G20+H20+I20+J20+K20+L20 -> 19500
A21: 18/12/2025 | E21: =6000 -> 6000 | F21: =2000 -> 2000 | G21: =33200+5000+5200+15000+14000+9200 -> 81600 | M21: =B21+C21+D21+E21+F21+G21+H21+I21+J21+K21+L21 -> 89600
A22: 19/12/2025 | E22: =2000 -> 2000 | F22: =2000 -> 2000 | G22: =5000+5500+2000+40650 -> 53150 | M22: =B22+C22+D22+E22+F22+G22+H22+I22+J22+K22+L22 -> 57150
A23: 20/12/2025 | E23: =4000+1000+6000+6000+5000 -> 22000 | G23: =26000+11000+5200+25400 -> 67600 | M23: =B23+C23+D23+E23+F23+G23+H23+I23+J23+K23+L23 -> 89600
A24: 21/12/2025 | E24: =1000 -> 1000 | G24: =35000+21300+5000+20000 -> 81300 | M24: =B24+C24+D24+E24+F24+G24+H24+I24+J24+K24+L24 -> 82300
A25: 22/12/2025 | G25: =3200+6000+20000+5000+1500+8500 -> 44200 | M25: =B25+C25+D25+E25+F25+G25+H25+I25+J25+K25+L25 -> 44200
A26: 23/12/2025 | G26: =13500+8000+5000 -> 26500 | M26: =B26+C26+D26+E26+F26+G26+H26+I26+J26+K26+L26 -> 26500 | Q26: =8000+15000+57200+12000+7200+37300+36800+15000+30000+5000+3200+10000+5500+32000+13000+20000+20000+10000+6500+20000+20000+25000+73000+20000+1000+59000+9300+30200+7000+9200+15200+5000+4200+26200 -> 668000 | S26: =253550-102250 -> 151300 | T26: =S26-231530-70300 -> -150530
A27: 24/12/2025 | E27: =3000 -> 3000 | G27: =15000+14000+1000+10500+13000+1500 -> 55000 | M27: =B27+C27+D27+E27+F27+G27+H27+I27+J27+K27+L27 -> 58000 | Q27: =1000+9200+2000+35200+2000+42650+20000+6000+4000+17000+25400+20000+15000+21300+183250+20000+3200+8500+20000+5000+13500+20000+7500+20000+8500+32300+23000+37000+8000+27000+41600+19200+14000+8000+32400+6200+56000+38200 -> 873100 | S27: =470200-Q27 -> -402900 | T27: =S27+T26+24450 -> -528980
A28: 25/12/2025 | E28: =8500 -> 8500 | G28: =20000+20000+7500 -> 47500 | M28: =B28+C28+D28+E28+F28+G28+H28+I28+J28+K28+L28 -> 56000 | Q28: =31400+3800+5200+20000+10000+20000+10000+6500+54200+22200+23200+7000+19200+18300+29450+12200+10000 -> 302650 | S28: =546900-Q28 -> 244250 | T28: =S28+T27-166800 -> -451530
A29: 26/12/2025 | E29: =1000 -> 1000 | F29: =4000 -> 4000 | G29: =12000+30300+37000+27000+23000+39600 -> 168900 | M29: =B29+C29+D29+E29+F29+G29+H29+I29+J29+K29+L29 -> 173900 | Q29: =2000+7200+14000+30200+10000+26300+13000+17000+8500+15000 -> 143200
A30: 27/12/2025 | E30: =1000+2000+1000 -> 4000 | F30: =6000 -> 6000 | G30: =6000+9200+10000+14000+5200+30400+27200+3200+6200+7000+6500+6000+34200+8000 -> 173100 | M30: =B30+C30+D30+E30+F30+G30+H30+I30+J30+K30+L30 -> 183100
A31: 28/12/2025 | G31: =31400+1000+3800+3000+46500+4400+2800+3000 -> 95900 | M31: =B31+C31+D31+E31+F31+G31+H31+I31+J31+K31+L31 -> 95900 | Q31: =SUM(Q25:Q30) -> 1986950
A32: 29/12/2025 | E32: =1000+6500 -> 7500 | F32: =10000 -> 10000 | G32: =10000+3000+15000+20000+1500+7500+4500+2200+1500+4400+5000+10000+20000+1000+2000+24200+39000+7000 -> 177800 | M32: =B32+C32+D32+E32+F32+G32+H32+I32+J32+K32+L32 -> 195300
A33: 30/12/2025 | E33: =7000 -> 7000 | F33: =4000 -> 4000 | G33: =5200+7200+15000+4000+50200+22200+23200+18200+11000+2000+13300+19700+4000+19300+29000 -> 243500 | M33: =B33+C33+D33+E33+F33+G33+H33+I33+J33+K33+L33 -> 254500
A34: 31/12/2025 | E34: =13000+17000 -> 30000 | G34: =30200+14000+8500+10000+7200+8500+5500 -> 83900 | M34: =B34+C34+D34+E34+F34+G34+H34+I34+J34+K34+L34 -> 113900
B35: =SUM(B4:B34) -> 0 | C35: =SUM(C4:C34) -> 0 | D35: =SUM(D4:D34) -> 0 | E35: =SUM(E4:E34) -> 197600 | F35: =SUM(F4:F34) -> 48000 | G35: =SUM(G4:G34) -> 2381500 | H35: =SUM(H4:H34) -> 0 | I35: =SUM(I4:I34) -> 0 | ... M35: =SUM(M4:M34) -> 2627100
D37: %
B38: CARD | D38: =B35/M35*100 -> 0
B39: SURCHARGE | D39: =C35/M35*100 -> 0
B40: SURGERY | D40: =D35/M35*100 -> 0 | H40: N
B41: =E3 -> LAB | D41: =E35/M35*100 -> 7.5216018
B42: BED | D42: =F35/M35*100 -> 1.8271097 | G42: SALES | H42: =E35+G35+H35+I35+L35+J35 -> 2579100
...

Sheet GEN.EXPENSES
A1: DATE | B1: PARTICULARS | D1: Invoice No. | E1: AMOUNT
A2: 45700 | B2: CHANGEOVER,WIRE & LABOUR | E2: 109000
A3: 45700 | B3: A4 PAPER,STET,BULBS, EXTENSION | E3: =4000+6000+9000+4000 -> 23000
A4: 45700 | B4: FOLDER PART PAYMENT | E4: 150000
A5: 45700 | B5: PAINTING | E5: 40000
A6: 45700 | B6: FUEL | E6: 50000
A7: 45700 | B7: TRANSPORT FOR MEDICATION JAMES | E7: 1500
A8: 45700 | B8: SIGN POST WAYBILL | E8: 2000
A9: 45700 | B9: WEEDING | E9: 3000
A10: 45700 | B10: BASIN & BASKET | E10: 23500 | L10: =13500+17000+14000+5000+10000 -> 59500
A11: 45700 | B11: FUEL | E11: 31500
A12: 45700 | B12: LANCET | E12: 3500
A13: 45700 | B13: PLUMBING WORK | E13: 2500
A14: 45700 | B14: REPAIR OF GEN | E14: 42000 | L14: =2013100-1500000 -> 513100
A15: 45700 | B15: STORE PURCHASE:MEDICINE | E15: 12500
A16: 45700 | B16: FUEL | E16: 50000
A17: 45700 | B17: REFUND | E17: 65700
A18: 45700 | B18: REFUND | E18: 7500
A19: 46003 | B19: LAB | E19: 5500
A20: 46003 | B20: STORE PURCHASE:MEDICINE | E20: 513100
A21: 46003 | B21: OFFICE SUPPLY | E21: 49500
A22: 46003 | B22: POLICE | E22: 10000
A23: 46003 | B23: JAMES | E23: 1000
A24: 46003
A25: 46003
A26: 46003
A27: 46003
A28: 46003
A29: 46003 | C29: EKWUEME
A30: 46003
A31: 46003
A32: 46003
A33: 46003
A34: 27/9/2025
A35: 27/9/2025
E39: =SUM(E2:E38) -> 1196300

Sheet FIN. REPORT
A2: STATEMENT OF FINANCIAL PERFORMANCE FOR THE MONTH ENDED 31/12/2025
B3: N | C3: N
A4: REVENUE (CASH) | C4: =REVENUE!M35 -> 2627100
A5: Stock @ 1/12/2025 | B5: 1450000
A6: Add PURCHASES | B6: =MEDICATIONS!E18 -> 536100
A7: Add Carriage
A8: Less STOCK AS AT 31/12/2025 | B8: 1610000
A9: COST OF SALES | C9: =B5+B6+B7-B8 -> 376100
A10: GROSS PROFIT | C10: =C4-C9 -> 2251000
A11: EXPENSES
A12: SALARIES | B12: =170000+1445000 -> 1615000
A13: OFFICE SUPPLIES | B13: ='MAINTENANCE-OFFICE SUPPLIES'!E21 -> 528700
A14: POWER/LIGHTING | B14: ='MAINTENANCE-OFFICE SUPPLIES'!E30 -> 131500
A15: WAGES
A16: TRANSPORT | C16: =B12+B13+B14+B15+B16 -> 2275200
A17: NET PROFIT/LOSS | C17: =C10-C16 -> -24200
A21: INDEGENT | C21: =13500+84000+16200+8000+9200+20400+5000+18200+65800+8000 -> 248300
A22: DEMENTIA | C22: 25800
A23: CHRONIC HEALTH | C23: 312000
A24: PSYCHIATRICS | C24: 148000
C25: =C21+C22+C23+C24 -> 734100
A26: ACTUAL NET PROFIT | C26: =C17+C25 -> 709900

Sheet MAINTENANCE-OFFICE SUPPLIES
A1: DATE | B1: PARTICULARS | D1: Invoice No. | E1: AMOUNT
A2: 45700 | B2: CHANGEOVER,WIRE & LABOUR | E2: 109000
A3: 45700 | B3: A4 PAPER,STET,BULBS, EXTENSION | E3: =4000+6000+9000+4000 -> 23000
A4: 45700 | B4: FOLDER PART PAYMENT | E4: 150000
A5: 45700 | B5: PAINTING | E5: 40000
A6: 45700 | B6: SIGN POST WAYBILL | E6: 2000
A7: 45700 | B7: WEEDING | E7: 3000
A8: 45700 | B8: BASIN & BASKET | E8: 23500 | L8: =13500+17000+14000+5000+10000 -> 59500
A9: 45700 | B9: PLUMBING WORK | E9: 2500
A10: 45700 | B10: REPAIR OF GEN | E10: 42000 | L10: =2013100-1500000 -> 513100
A11: 45700 | B11: REFUND | E11: 65700
A12: 45700 | B12: REFUND | E12: 7500
A13: 46003 | B13: OFFICE SUPPLY | E13: 49500
A14: 46003 | B14: POLICE | E14: 10000
A15: 46003 | B15: JAMES | E15: 1000
B21: TOTAL | E21: =SUM(E2:E20) -> 528700
A26: 45700 | B26: FUEL | E26: 50000
A27: 13/12/2025 | B27: FUEL | E27: 31500
A28: 26/12/2025 | B28: FUEL | E28: 50000
E30: =SUM(E26:E29) -> 131500

Sheet MEDICATIONS
A1: 45700 | B1: TRANSPORT FOR MEDICATION JAMES | E1: 1500
A2: 45700 | B2: LANCET | E2: 3500
A3: 45700 | B3: STORE PURCHASE:MEDICINE | E3: 12500
A4: 46003 | B4: LAB | E4: 5500
A5: 46003 | B5: STORE PURCHASE:MEDICINE | E5: 513100
E18: =SUM(E1:E17) -> 536100
E24: =SUM(E21:E23) -> 0
E26: =E19+E24 -> 0
C29: medi | D29: =E19 -> 0
C30: carriage | D30: =E24 -> 0
D32: =D29+D30+D31 -> 0

Sheet SUMMARY
A2: SUMMARY
B3: OPENING STOCK | F3: 1450000
B4: PURCHASES | F4: 536100
B5: DONATION
B6: TOTAL STOCK | F6: =F3+F4+F5 -> 1986100
A10: NUMBER OF PATIENTS SEEN IN DEC,2025
B11: PSYCHIATRICS | F11: 18
B12: MALE | F12: 91
B13: FEMALE | F13: 96
B14: TOTAL | F14: =F12+F13+F11 -> 205
B15: ADMISSION | F15: 24DAYS
A17: OTHER POINTS TO NOTE
A18: WE STILL HAVE STOCK (MEDICATION) VALUED N1,610,000 AT COST PRICE AND DEBT OF( N394,730).
A19: DIRECT DEPOSIT N1,986,150
A20: CASH RECEIVED IS N641,150 AND USED TO FUND EXPENSES
A21: AMOUNT SPENT ON MAINTENANCE,STOREPURCHASE, CLEARANCE OF OLD DEPT AND OFFICE SUPPLY N1,196,300
A22: COST OF INDEGENT,DELIVERY SUBSIDY, DEMENTIA,CHRONIC CARE AND BLOOM SCHOLARS N734,100
A23: WE LOST N53,900 TO UNCREDITED TRANSACTION

Sheet LAB.
A2: STATEMENT OF FINANCIAL PERFORMANCE FOR THE MONTH ENDED 31/12/2025
B3: N | C3: N
A4: REVENUE (CASH) | C4: =REVENUE!E35 -> 197600
A5: Stock @ 1/12/2025 | B5: 340000
A6: Add PURCHASES | B6: 68000
A7: Add Carriage | B7: 5000
A8: Less STOCK AS AT 31/12/2025 | B8: 349000
A9: COST OF SALES | C9: =B5+B6+B7-B8 -> 64000
A10: GROSS PROFIT | C10: =C4-C9 -> 133600
A11: EXPENSES
A12: SALARIES | B12: 145000
A13: OFFICE SUPPLIES | B13: 5000
A14: POWER/LIGHTING | B14: 20000
A15: WAGES
A16: TRANSPORT | C16: =B12+B13+B14+B15+B16 -> 170000
A17: NET PROFIT/LOSS | C17: =C10-C16 -> -36400
A21: INDEGENT | C21: -29000
A22: CHRONIC HEALTH
A23: BLOOMS SCHOLARS
A24: PSYCHIATRICS
C25: =C21+C22+C23+C24 -> -29000
A26: ACTUAL NET PROFIT | C26: =C17+C25 -> -65400

Sheet STOCK
A1: COST OF MATERIAL USAGE FOR THE MONTH OF NOV. 2025
A2: NOV,2025
G3: QTY SOLD | H3: U/PRICE | I3: AMOUNT | J3: MINIMUM | K3: MAXIMUM
A4: ANTI HYPERTENSIVE
A5: METHYLDOPA | B5: 70 | D5: =B5+C5 -> 70 | E5: 30 | G5: =D5-E5-F5 -> 40 | H5: 30 | I5: =G5*H5 -> 1200 | J5: 50 | K5: 200
A6: AMILODIPINE 10MG | D6: =B6+C6 -> 0 | G6: =D6-E6-F6 -> 0 | H6: 30 | I6: =G6*H6 -> 0 | J6: 1000 | K6: 8000
A7: AMILODIPINE 5MG | B7: 1000 | C7: 1000 | D7: =B7+C7 -> 2000 | E7: 2000 | G7: =D7-E7-F7 -> 0 | H7: 30 | I7: =G7*H7 -> 0 | J7: 1000 | K7: 8000
A8: LISINOPRIL 2MG | B8: 10 | C8: 20 | D8: =B8+C8 -> 30 | E8: 10 | G8: =D8-E8-F8 -> 20 | H8: 300 | I8: =G8*H8 -> 6000 | J8: 1000 | K8: 8000
A9: CARVIDOLOL 6.25MG | D9: =B9+C9 -> 0 | G9: =D9-E9-F9 -> 0 | H9: 30 | I9: =G9*H9 -> 0 | J9: 1000 | K9: 4000
A10: NIFIDIPINE 90MG | B10: 20 | C10: 1000 | D10: =B10+C10 -> 1020 | E10: 1000 | G10: =D10-E10-F10 -> 20 | H10: 20 | I10: =G10*H10 -> 400 | J10: 1000 | K10: 5000
A11: VASOPRINE 75MG | D11: =B11+C11 -> 0 | G11: =D11-E11-F11 -> 0 | H11: 500 | I11: =G11*H11 -> 0 | J11: 200 | K11: 2000
A12: MET/GMPAGHPHOZINE | B12: 56 | D12: =B12+C12 -> 56 | E12: 33 | G12: =D12-E12-F12 -> 23 | H12: 10 | I12: =G12*H12 -> 230 | J12: 30 | K12: 5000
A13: HCTZ 20MG | B13: 8000 | D13: =B13+C13 -> 8000 | E13: 7000 | G13: =D13-E13-F13 -> 1000 | H13: 20 | I13: =G13*H13 -> 20000 | J13: 1000 | K13: 5000
A14: LORATIDINE | D14: =B14+C14 -> 0 | G14: =D14-E14-F14 -> 0 | H14: 1500 | I14: =G14*H14 -> 0 | J14: 20 | K14: 100
A15: DICLOFENAC | B15: 100 | D15: =B15+C15 -> 100 | E15: 60 | G15: =D15-E15-F15 -> 40 | H15: 100 | I15: =G15*H15 -> 4000 | J15: 20 | K15: 200
A16: METROPROLOL | D16: =B16+C16 -> 0 | G16: =D16-E16-F16 -> 0 | H16: 5 | I16: =G16*H16 -> 0 | J16: 20 | K16: 200
A17: LABETALOL | D17: =B17+C17 -> 0 | G17: =D17-E17-F17 -> 0 | H17: 900 | I17: =G17*H17 -> 0 | J17: 10 | K17: 50
A18: ALDOMENT | D18: =B18+C18 -> 0 | G18: =D18-E18-F18 -> 0 | H18: 850 | I18: =G18*H18 -> 0 | J18: 10 | K18: 50
A19: LABETALOL INJ. | C19: 2 | D19: =B19+C19 -> 2 | E19: 2 | G19: =D19-E19-F19 -> 0 | H19: 1300 | I19: =G19*H19 -> 0 | J19: 5 | K19: 20
D20: =B20+C20 -> 0 | G20: =D20-E20-F20 -> 0 | I20: =G20*H20 -> 0 | J20: 30 | K20: 1000
A21: MENTAL | D21: =B21+C21 -> 0 | G21: =D21-E21-F21 -> 0 | I21: =G21*H21 -> 0
A22: AMITRIPTYLINE | B22: 20 | D22: =B22+C22 -> 20 | E22: 20 | G22: =D22-E22-F22 -> 0 | H22: 25 | I22: =G22*H22 -> 0
A23: STELAZINE | B23: 150 | D23: =B23+C23 -> 150 | E23: 150 | G23: =D23-E23-F23 -> 0 | H23: 50 | I23: =G23*H23 -> 0 | J23: 200 | K23: 2000
A24: ARTANE | B24: 250 | D24: =B24+C24 -> 250 | E24: 200 | G24: =D24-E24-F24 -> 50 | H24: 70 | I24: =G24*H24 -> 3500 | J24: =K24/10 -> 200 | K24: 2000
A25: CARBAMEZAPINE | B25: 25 | D25: =B25+C25 -> 25 | E25: 20 | G25: =D25-E25-F25 -> 5 | H25: 70 | I25: =G25*H25 -> 350 | J25: =K25/10 -> 200 | K25: 2000
A26: LAGATIL | B26: 25 | C26: 100 | D26: =B26+C26 -> 125 | E26: 85 | G26: =D26-E26-F26 -> 40 | H26: 100 | I26: =G26*H26 -> 4000 | J26: =K26/10 -> 200 | K26: 2000
A27: PHENOBARB | B27: 50 | D27: 105 | E27: 95 | G27: =D27-E27-F27 -> 10 | H27: 50 | I27: =G27*H27 -> 500 | J27: =K27/10 -> 200 | K27: 2000
A28: MONTELUKAST | B28: 90 | D28: =B28+C28 -> 90 | E28: 90 | G28: =D28-E28-F28 -> 0 | H28: 60 | I28: =G28*H28 -> 0 | J28: =K28/10 -> 250 | K28: 2500
J29: =K29/10 -> 20 | K29: 200
A30: ANTI DIABETIC | D30: =B30+C30 -> 0 | G30: =D30-E30-F30 -> 0 | I30: =G30*H30 -> 0
A31: INSULIN | D31: =B31+C31 -> 0 | G31: =D31-E31-F31 -> 0 | H31: 6200 | I31: =G31*H31 -> 0 | J31: =K31/10 -> 0
A32: METFORMIN | B32: 5000 | D32: =B32+C32 -> 5000 | E32: 4500 | G32: =D32-E32-F32 -> 500 | H32: 20 | I32: =G32*H32 -> 10000 | J32: =K32/10 -> 10 | K32: 100
A33: GLIPIZIDE | D33: =B33+C33 -> 0 | G33: =D33-E33-F33 -> 0 | H33: 30 | I33: =G33*H33 -> 0 | J33: =K33/10 -> 500 | K33: 5000
D34: =B34+C34 -> 0 | G34: =D34-E34-F34 -> 0 | I34: =G34*H34 -> 0 | J34: =K34/10 -> 200 | K34: 2000
A35: MULTIVITAMINE | D35: =B35+C35 -> 0 | G35: =D35-E35-F35 -> 0 | I35: =G35*H35 -> 0 | J35: =K35/10 -> 0
A36: FOLIC ACID | B36: 1500 | C36: 1000 | D36: =B36+C36 -> 2500 | E36: 2000 | G36: =D36-E36-F36 -> 500 | H36: 6 | I36: =G36*H36 -> 3000 | J36: =K36/10 -> 0
A37: FESOLATE | B37: 1500 | C37: 1000 | D37: =B37+C37 -> 2500 | E37: 2000 | G37: =D37-E37-F37 -> 500 | H37: 6 | I37: =G37*H37 -> 3000 | J37: =K37/10 -> 1000 | K37: 10000
A38: VITAMINE-C | B38: 3000 | D38: =B38+C38 -> 3000 | E38: 2000 | G38: =D38-E38-F38 -> 1000 | H38: 10 | I38: =G38*H38 -> 10000 | J38: =K38/10 -> 1000 | K38: 10000
A39: VITAMINE-C 1000MG | D39: =B39+C39 -> 0 | G39: =D39-E39-F39 -> 0 | H39: 30 | I39: =G39*H39 -> 0 | J39: =K39/10 -> 1000 | K39: 10000
A40: VITAMINE-E 1000MG | B40: 20 | D40: =B40+C40 -> 20 | G40: =D40-E40-F40 -> 20 | H40: 50 | I40: =G40*H40 -> 1000 | J40: =K40/10 -> 1000 | K40: 10000
...

Sheet CLOSING STOCK
A1: COST OF MATERIAL USAGE FOR THE MONTH OF DEC. 2025
A2: DEC,2025
G3: QTY SOLD | H3: U/PRICE | I3: AMOUNT
A4: ANTI HYPERTENSIVE
A5: METHYLDOPA | B5: 30 | D5: =B5+C5 -> 30 | G5: =D5-E5-F5 -> 30 | H5: 30 | I5: =G5*H5 -> 900
A6: AMILODIPINE 10MG | D6: =B6+C6 -> 0 | G6: =D6-E6-F6 -> 0 | H6: 30 | I6: =G6*H6 -> 0
A7: AMILODIPINE 5MG | B7: 2000 | D7: =B7+C7 -> 2000 | G7: =D7-E7-F7 -> 2000 | H7: 30 | I7: =G7*H7 -> 60000
A8: LISINOPRIL 2MG | B8: 10 | D8: =B8+C8 -> 10 | G8: =D8-E8-F8 -> 10 | H8: 300 | I8: =G8*H8 -> 3000
A9: CARVIDOLOL 6.25MG | D9: =B9+C9 -> 0 | G9: =D9-E9-F9 -> 0 | H9: 30 | I9: =G9*H9 -> 0
A10: NIFIDIPINE 90MG | B10: 1000 | D10: =B10+C10 -> 1000 | G10: =D10-E10-F10 -> 1000 | H10: 20 | I10: =G10*H10 -> 20000
A11: VASOPRINE 75MG | D11: =B11+C11 -> 0 | G11: =D11-E11-F11 -> 0 | H11: 500 | I11: =G11*H11 -> 0
A12: MET/GMPAGHPHOZINE | B12: 33 | D12: =B12+C12 -> 33 | G12: =D12-E12-F12 -> 33 | H12: 10 | I12: =G12*H12 -> 330
A13: HCTZ 20MG | B13: 7000 | D13: =B13+C13 -> 7000 | G13: =D13-E13-F13 -> 7000 | H13: 20 | I13: =G13*H13 -> 140000
A14: LORATIDINE | D14: =B14+C14 -> 0 | G14: =D14-E14-F14 -> 0 | H14: 1500 | I14: =G14*H14 -> 0
A15: DICLOFENAC | B15: 60 | D15: =B15+C15 -> 60 | G15: =D15-E15-F15 -> 60 | H15: 100 | I15: =G15*H15 -> 6000
A16: METROPROLOL | D16: =B16+C16 -> 0 | G16: =D16-E16-F16 -> 0 | H16: 5 | I16: =G16*H16 -> 0
A17: LABETALOL | D17: =B17+C17 -> 0 | G17: =D17-E17-F17 -> 0 | H17: 900 | I17: =G17*H17 -> 0
A18: ALDOMENT | D18: =B18+C18 -> 0 | G18: =D18-E18-F18 -> 0 | H18: 850 | I18: =G18*H18 -> 0
A19: LABETALOL INJ. | B19: 2 | D19: =B19+C19 -> 2 | G19: =D19-E19-F19 -> 2 | H19: 1300 | I19: =G19*H19 -> 2600
D20: =B20+C20 -> 0 | G20: =D20-E20-F20 -> 0 | I20: =G20*H20 -> 0
A21: MENTAL | D21: =B21+C21 -> 0 | G21: =D21-E21-F21 -> 0 | I21: =G21*H21 -> 0
A22: AMITRIPTYLINE | B22: 20 | D22: =B22+C22 -> 20 | G22: =D22-E22-F22 -> 20 | H22: 25 | I22: =G22*H22 -> 500
A23: STELAZINE | B23: 150 | D23: =B23+C23 -> 150 | G23: =D23-E23-F23 -> 150 | H23: 50 | I23: =G23*H23 -> 7500
A24: ARTANE | B24: 200 | D24: =B24+C24 -> 200 | G24: =D24-E24-F24 -> 200 | H24: 70 | I24: =G24*H24 -> 14000
A25: CARBAMEZAPINE | B25: 20 | D25: =B25+C25 -> 20 | G25: =D25-E25-F25 -> 20 | H25: 70 | I25: =G25*H25 -> 1400
A26: LAGATIL | B26: 85 | D26: =B26+C26 -> 85 | G26: =D26-E26-F26 -> 85 | H26: 100 | I26: =G26*H26 -> 8500
A27: PHENOBARB | B27: 95 | D27: 105 | G27: =D27-E27-F27 -> 105 | H27: 50 | I27: =G27*H27 -> 5250
A28: MONTELUKAST | B28: 90 | D28: =B28+C28 -> 90 | G28: =D28-E28-F28 -> 90 | H28: 60 | I28: =G28*H28 -> 5400
A29: ANTI DIABETIC | D29: =B29+C29 -> 0 | G29: =D29-E29-F29 -> 0 | I29: =G29*H29 -> 0
A30: INSULIN | D30: =B30+C30 -> 0 | G30: =D30-E30-F30 -> 0 | H30: 6200 | I30: =G30*H30 -> 0
A31: METFORMIN | B31: 4500 | D31: =B31+C31 -> 4500 | G31: =D31-E31-F31 -> 4500 | H31: 20 | I31: =G31*H31 -> 90000
A32: GLIPIZIDE | D32: =B32+C32 -> 0 | G32: =D32-E32-F32 -> 0 | H32: 30 | I32: =G32*H32 -> 0
D33: =B33+C33 -> 0 | G33: =D33-E33-F33 -> 0 | I33: =G33*H33 -> 0
A34: MULTIVITAMINE | D34: =B34+C34 -> 0 | G34: =D34-E34-F34 -> 0 | I34: =G34*H34 -> 0
A35: FOLIC ACID | B35: 2000 | D35: =B35+C35 -> 2000 | G35: =D35-E35-F35 -> 2000 | H35: 6 | I35: =G35*H35 -> 12000
A36: FESOLATE | B36: 2000 | D36: =B36+C36 -> 2000 | G36: =D36-E36-F36 -> 2000 | H36: 6 | I36: =G36*H36 -> 12000
A37: VITAMINE-C | B37: 2000 | D37: =B37+C37 -> 2000 | G37: =D37-E37-F37 -> 2000 | H37: 10 | I37: =G37*H37 -> 20000
A38: VITAMINE-C 1000MG | D38: =B38+C38 -> 0 | G38: =D38-E38-F38 -> 0 | H38: 30 | I38: =G38*H38 -> 0
A39: VITAMINE-E 1000MG | D39: =B39+C39 -> 0 | G39: =D39-E39-F39 -> 0 | H39: 50 | I39: =G39*H39 -> 0
A40: VITAMINE-C SYRUP | B40: 10 | D40: =B40+C40 -> 10 | G40: =D40-E40-F40 -> 10 | H40: 700 | I40: =G40*H40 -> 7000
...
