Workbook

Sheet OctRev25
A1: DATE | B1: Revenue Category | C1: Amount | D1: Source Month
A2: 45931 | B2: LAB | C2: 12000 | D2: Oct-2025
A3: 45931 | B3: DRUGS | C3: 4500 | D3: Oct-2025
A4: 45932 | B4: LAB | C4: 17000 | D4: Oct-2025
A5: 45932 | B5: DRUGS | C5: 162850 | D5: Oct-2025
A6: 45933 | B6: LAB | C6: 23500 | D6: Oct-2025
A7: 45933 | B7: DRUGS | C7: 93600 | D7: Oct-2025
A8: 45934 | B8: LAB | C8: 19000 | D8: Oct-2025
A9: 45934 | B9: DRUGS | C9: 76700 | D9: Oct-2025
A10: 45935 | B10: DRUGS | C10: 161300 | D10: Oct-2025
A11: 45936 | B11: LAB | C11: 15000 | D11: Oct-2025
A12: 45936 | B12: DRUGS | C12: 25000 | D12: Oct-2025
A13: 45937 | B13: LAB | C13: 24000 | D13: Oct-2025
... A59: 45961 | B59: DRUGS | C59: 102200 | D59: Oct-2025

Sheet OctExp25
A1: DATE | B1: PARTICULARS | C1: Expense Category | D1: SUPPLIER | E1: AMOUNT | F1: Source Month
A2: 45932 | B2: FUEL | C2: Fuel | E2: 50000 | F2: Oct-2025
A3: 45932 | B3: REFUND TO CHARLSE | C3: Maintenance | E3: 3000 | F3: Oct-2025
A4: 45932 | B4: STORE PURCHASE:MEDICINE | C4: Medication | D4: GRACE & MERCY | E4: 52000 | F4: Oct-2025
A5: 45932 | B5: WAYBILL | C5: Transportation | E5: 3000 | F5: Oct-2025
A6: 45932 | B6: STORE PURCHASE:STRIP | C6: Medical Supplies | D6: GRACE & MERCY | E6: 10000 | F6: Oct-2025
A7: 45936 | B7: PLUMBING MATERIAL | C7: Maintenance | E7: 6000 | F7: Oct-2025
A8: 45936 | B8: LABOUR | C8: Maintenance | E8: 5000 | F8: Oct-2025
A9: 45936 | B9: POVIDON | C9: Medical Supplies | E9: 14000 | F9: Oct-2025
A10: 45936 | B10: OFFICE SUPPLY : EXERCISE BOOKS, BATTERY | C10: Office Supplies | E10: 3000 | F10: Oct-2025
A11: 45936 | B11: STORE PURCHASE:MEDICINE (LOCAL) | C11: Medication | E11: 5000 | F11: Oct-2025
A12: 45936 | B12: REPAIR OF GEN | C12: Maintenance | E12: 1000 | F12: Oct-2025
A13: 45936 | B13: PLUMBING WORK | C13: Maintenance | D13: EKWUEME | E13: 146500 | F13: Oct-2025
A14: 45946 | B14: PLASTER | C14: Medical Supplies | E14: 3000 | F14: Oct-2025
A15: 45946 | B15: REFUND | C15: Maintenance | E15: 1500 | F15: Oct-2025
A16: 45946 | B16: FUEL | C16: Fuel | E16: 51000 | F16: Oct-2025
A17: 45946 | B17: REPAIR OF CHANGE OVER | C17: Maintenance | E17: 3800 | F17: Oct-2025
A18: 45960 | B18: TRANSPORT FOR CHINENYE | C18: Transportation | E18: 5000 | F18: Oct-2025
A19: 45960 | B19: STORE PURCHASE:MEDICINE | C19: Medication | E19: 64500 | F19: Oct-2025
A20: 45960 | B20: CARRIAGE | C20: Transportation | E20: 2000 | F20: Oct-2025
A21: 45960 | B21: STORE PURCHASE:MEDICINE | C21: Medication | D21: ALVICE MEDICALS | E21: 480000 | F21: Oct-2025
A22: 45960 | B22: STORE PURCHASE:MEDICINE | C22: Medication | D22: BLESSED MEKUS | E22: 162800 | F22: Oct-2025
A23: 45960 | B23: BANK CHARGES | C23: Maintenance | E23: 365 | F23: Oct-2025
A24: 45961 | B24: SALARY | C24: Salary | E24: 1615000 | F24: Oct-2025

Sheet REVENUE
A1: REVENUE ASSURANCE REPORT FOR OCTOBER 2025
A3: DATE | B3: CARD | C3: SURCHARGE | D3: SURGERY | E3: LAB | F3: BED | G3: DRUGS | H3: DELIVERY | I3: MENTAL | J3: WATER | K3: P. REPORT | L3: DRESSING | M3: TOTAL
A4: 45931 | E4: =2000+10000 -> 12000 | G4: =4500 -> 4500 | M4: =B4+C4+D4+E4+F4+G4+H4+I4+J4+K4+L4 -> 16500
A5: 45932 | E5: =17000 -> 17000 | G5: =3200+14900+2000+1800+2800+15200+20300+41450+61200 -> 162850 | M5: =B5+C5+D5+E5+F5+G5+H5+I5+J5+K5+L5 -> 179850
A6: 45933 | E6: =14000+7500+2000 -> 23500 | G6: =1500+9200+36500+1000+8200+8200+29000 -> 93600 | M6: =B6+C6+D6+E6+F6+G6+H6+I6+J6+K6+L6 -> 117100
A7: 45934 | E7: =18000+1000 -> 19000 | G7: =12500+3000+20000+40000+1200 -> 76700 | M7: =B7+C7+D7+E7+F7+G7+H7+I7+J7+K7+L7 -> 95700
A8: 45935 | G8: =4200+16000+15000+28350+97750 -> 161300 | M8: =B8+C8+D8+E8+F8+G8+H8+I8+J8+K8+L8 -> 161300
A9: 45936 | E9: =3000+2000+9000+1000 -> 15000 | G9: =6500+8000+1500+1000+1000+2000+5000 -> 25000 | M9: =B9+C9+D9+E9+F9+G9+H9+I9+J9+K9+L9 -> 40000
A10: 45937 | E10: =1000+7000+1000+15000 -> 24000 | G10: =10500+1500+3500+2000+9800+2000+20000+1500+3000 -> 53800 | L10: 10000 | M10: =B10+C10+D10+E10+F10+G10+H10+I10+J10+K10+L10 -> 87800
A11: 45938 | E11: =6000 -> 6000 | G11: =10000+7000 -> 17000 | L11: 1000 | M11: =B11+C11+D11+E11+F11+G11+H11+I11+J11+K11+L11 -> 24000
A12: 45939 | E12: =1000+8000+14000 -> 23000 | G12: =11000+8000+2500+6200 -> 27700 | M12: =B12+C12+D12+E12+F12+G12+H12+I12+J12+K12+L12 -> 50700
A13: 45940 | E13: =9000 -> 9000 | G13: =3200+4200+9500 -> 16900 | M13: =B13+C13+D13+E13+F13+G13+H13+I13+J13+K13+L13 -> 25900
A14: 45941 | G14: =3000+10000+28000 -> 41000 | L14: =1000 -> 1000 | M14: =B14+C14+D14+E14+F14+G14+H14+I14+J14+K14+L14 -> 42000
A15: 45942 | G15: =50000+41300+1500 -> 92800 | M15: =B15+C15+D15+E15+F15+G15+H15+I15+J15+K15+L15 -> 92800
A16: 45943 | E16: =5000+2000 -> 7000 | G16: =7200+2000 -> 9200 | M16: =B16+C16+D16+E16+F16+G16+H16+I16+J16+K16+L16 -> 16200
A17: 14/10/2025 | E17: =7500 -> 7500 | G17: =15000+1500+1000 -> 17500 | M17: =B17+C17+D17+E17+F17+G17+H17+I17+J17+K17+L17 -> 25000
A18: 15/10/2025 | E18: =2000 -> 2000 | G18: =1500+9200 -> 10700 | M18: =B18+C18+D18+E18+F18+G18+H18+I18+J18+K18+L18 -> 12700
A19: 16/10/2025 | E19: =5000+2000 -> 7000 | G19: =14300 -> 14300 | L19: =3000 -> 3000 | M19: =B19+C19+D19+E19+F19+G19+H19+I19+J19+K19+L19 -> 24300
A20: 17/10/2025 | E20: =1000+13000+8000+8000+5000 -> 35000 | G20: =9000+2200+9000 -> 20200 | M20: =B20+C20+D20+E20+F20+G20+H20+I20+J20+K20+L20 -> 55200
A21: 18/10/2025 | G21: =1000+1500+5500+1000+9800 -> 18800 | M21: =B21+C21+D21+E21+F21+G21+H21+I21+J21+K21+L21 -> 18800
A22: 19/10/2025 | E22: =1000 -> 1000 | G22: =29000+5200+5000 -> 39200 | M22: =B22+C22+D22+E22+F22+G22+H22+I22+J22+K22+L22 -> 40200
A23: 20/10/2025 | E23: =1000+6000+7000 -> 14000 | G23: =20000+1000+1000+7200 -> 29200 | M23: =B23+C23+D23+E23+F23+G23+H23+I23+J23+K23+L23 -> 43200
A24: 21/10/2025 | E24: =3000+3000+5000 -> 11000 | G24: =10000+1000+800+4500+6000+150000+46000+3000 -> 221300 | M24: =B24+C24+D24+E24+F24+G24+H24+I24+J24+K24+L24 -> 232300
A25: 22/10/2025 | G25: =6000+3500+5000+30000+13000+16000+1000+21500+1000 -> 97000 | M25: =B25+C25+D25+E25+F25+G25+H25+I25+J25+K25+L25 -> 97000
A26: 23/10/2025 | G26: =9500+4000+1000+3000 -> 17500 | M26: =B26+C26+D26+E26+F26+G26+H26+I26+J26+K26+L26 -> 17500 | Q26: =61200+6500+1800+14900+17000+15200+20300+14000+9200+20000+7500+8200+18000+29000+20000+40000+97750+28350+1500+6500+2000+1000+5000+20000+1000+15000+10500+7000+9800 -> 508200 | S26: =253550-102250 -> 151300 | T26: =S26-231530-70300 -> -150530
A27: 24/10/2025 | E27: =9000+6000+1000 -> 16000 | G27: =2000+5000+6500+30000+1400+14000 -> 58900 | M27: =B27+C27+D27+E27+F27+G27+H27+I27+J27+K27+L27 -> 74900 | Q27: =5000+7000+6200+3200+9500+50000+41300+1000+2000+2000+1500+9200 -> 137900 | S27: =470200-Q27 -> 332300 | T27: =S27+T26+24450 -> 206220
A28: 25/10/2025 | E28: =6000 -> 6000 | G28: =9000+16000+9200 -> 34200 | M28: =B28+C28+D28+E28+F28+G28+H28+I28+J28+K28+L28 -> 40200 | Q28: =5000+14300+5000+5000+9800+29000+5000+20000+7000+1000+7200+150000+3000+3000+46000+5000+800+16000+21500+1000+5000+14000+3000+30000+1000+16000+25600+1000+9200+50000+3200+7500+5000+16000+4500+2000+15000+4500+11700+13000 -> 591800 | S28: =546900-Q28 -> -44900 | T28: =S28+T27-166800 -> -5480
A29: 26/10/2025 | E29: =1000 -> 1000 | G29: =25600+5000+3000+2000+9200 -> 44800 | M29: =B29+C29+D29+E29+F29+G29+H29+I29+J29+K29+L29 -> 45800
A30: 27/10/2025 | G30: =3200+1000+4200+26200+50000+1500+12100 -> 98200 | M30: =B30+C30+D30+E30+F30+G30+H30+I30+J30+K30+L30 -> 98200
A31: 28/10/2025 | G31: =12800+6200+2000+4000+5000+1000+7500 -> 38500 | M31: =B31+C31+D31+E31+F31+G31+H31+I31+J31+K31+L31 -> 38500 | Q31: =SUM(Q25:Q30) -> 1237900
A32: 29/10/2025 | E32: =16000+5000 -> 21000 | G32: =4000+5500+5000+26500+6000+7000+3500+8000+2500+1000+4500+19200+3000+5000+20000+5000 -> 125700 | M32: =B32+C32+D32+E32+F32+G32+H32+I32+J32+K32+L32 -> 146700
A33: 30/10/2025 | E33: =15000+4000+10500 -> 29500 | G33: =30000+2000+3500+4500+10000+9500+10000 -> 69500 | M33: =B33+C33+D33+E33+F33+G33+H33+I33+J33+K33+L33 -> 99000
A34: 31/10/2025 | E34: =1500 -> 1500 | G34: =11700+6000+3500+11000+2000+20000+48000 -> 102200 | M34: =B34+C34+D34+E34+F34+G34+H34+I34+J34+K34+L34 -> 103700
B36: =SUM(B4:B34) -> 0 | C36: =SUM(C4:C34) -> 0 | D36: =SUM(D4:D34) -> 0 | E36: =SUM(E4:E34) -> 308000 | F36: =SUM(F4:F34) -> 0 | G36: =SUM(G4:G34) -> 1840050 | H36: =SUM(H4:H34) -> 0 | I36: =SUM(I4:I34) -> 0 | ... M36: =SUM(M4:M34) -> 2163050
D38: %
B39: CARD | D39: =B36/M36*100 -> 0
B40: SURCHARGE | D40: =C36/M36*100 -> 0
B41: SURGERY | D41: =D36/M36*100 -> 0 | H41: N
B42: =E3 -> LAB | D42: =E36/M36*100 -> 14.239153
B43: BED | D43: =F36/M36*100 -> 0 | G43: SALES | H43: =E36+G36+H36+I36+L36+J36 -> 2163050
...

Sheet ExpenseCat
A1: Keyword | B1: Expense Category
A2: MEDICINE | B2: Medication
A3: SYRINGE | B3: Medical Supplies
A4: GLOVE | B4: Medical Supplies
A5: NORMAL SALINE | B5: Medical Supplies
A6: SURGICAL EXPENSES | B6: Medical Supplies
A7: OFFICE SUPPLY | B7: Office Supplies
A8: FUEL | B8: Fuel
A9: ENGINE OIL | B9: Maintenance
A10: LABOUR | B10: Maintenance
A11: CEMENT | B11: Maintenance
A12: REPAIR | B12: Maintenance
... A41: 40 LEAVES | B41: Office Supplies

Sheet GEN.EXPENSES
A1: DATE | B1: PARTICULARS | C1: SUPPLIER | D1: AMOUNT
A2: 45932 | B2: FUEL | D2: 50000
A3: 45932 | B3: REFUND TO CHARLSE | D3: 3000
A4: 45932 | B4: STORE PURCHASE:MEDICINE | C4: GRACE & MERCY | D4: 52000
A5: 45932 | B5: WAYBILL | D5: 3000
A6: 45932 | B6: STORE PURCHASE:STRIP | C6: GRACE & MERCY | D6: 10000
A7: 45936 | B7: PLUMBING MATERIAL | D7: 6000
A8: 45936 | B8: LABOUR | D8: 5000
A9: 45936 | B9: POVIDON | D9: 14000
A10: 45936 | B10: OFFICE SUPPLY : EXERCISE BOOKS, BATTERY | D10: 3000
A11: 45936 | B11: STORE PURCHASE:MEDICINE (LOCAL) | D11: 5000
A12: 45936 | B12: REPAIR OF GEN | D12: 1000
A13: 45936 | B13: PLUMBING WORK | C13: EKWUEME | D13: 146500
A14: 16/10/2025 | B14: PLASTER | D14: 3000
A15: 16/10/2025 | B15: REFUND | D15: 1500
A16: 16/10/2025 | B16: FUEL | D16: 51000
A17: 16/10/2025 | B17: REPAIR OF CHANGE OVER | D17: 3800
A18: 30/10/2025 | B18: TRANSPORT FOR CHINENYE | D18: 5000
A19: 30/10/2025 | B19: STORE PURCHASE:MEDICINE | D19: 64500
A20: 30/10/2025 | B20: CARRIAGE | D20: 2000
A21: 30/10/2025 | B21: STORE PURCHASE:MEDICINE | C21: ALVICE MEDICALS | D21: 480000
A22: 30/10/2025 | B22: STORE PURCHASE:MEDICINE | C22: BLESSED MEKUS | D22: 162800
A23: 30/10/2025 | B23: BANK CHARGES | D23: 365
A24: 45961 | B24: SALARY | D24: =170000+1445000 -> 1615000

Sheet FIN. REPORT
A2: STATEMENT OF FINANCIAL PERFORMANCE FOR THE MONTH ENDED 31/10/2025
B3: N | C3: N
A4: REVENUE (CASH) | C4: =[1]REVENUE!M35 -> 2163050
A5: Stock @ 1/10/2025 | B5: 1579450
A6: Add PURCHASES | B6: =[1]MEDICATIONS!E18 -> 788300
A7: Add Carriage | B7: =[1]MEDICATIONS!E24 -> 5000
A8: Less STOCK AS AT 31/10/2025 | B8: 1450000
A9: COST OF SALES | C9: =B5+B6+B7-B8 -> 922750
A10: GROSS PROFIT | C10: =C4-C9 -> 1240300
A11: EXPENSES
A12: SALARIES | B12: =170000+1445000 -> 1615000
A13: OFFICE SUPPLIES | B13: ='[1]MAINTENANCE-OFFICE SUPPLIES'!E21 -> 178165
A14: POWER/LIGHTING | B14: ='[1]MAINTENANCE-OFFICE SUPPLIES'!E30 -> 101000
A15: WAGES
A16: TRANSPORT | C16: =B12+B13+B14+B15+B16 -> 1894165
A17: NET PROFIT/LOSS | C17: =C10-C16 -> -653865
A21: INDEGENT | C21: 108000
A22: DEMENTIA | C22: 27500
A23: BLOOMS | C23: 189500
A24: PSYCHIATRICS | C24: 123000
C25: =C21+C22+C23+C24 -> 448000
A26: ACTUAL NET LOSS | C26: =C17+C25 -> -205865

Sheet MAINTENANCE-OFFICE SUPPLIES
A1: DATE | B1: PARTICULARS | D1: Invoice No. | E1: AMOUNT
A2: 45698 | B2: REFUND TO CHARLSE | E2: 3000
A3: 45818 | B3: PLUMBING MATERIAL | E3: 6000
A4: 45818 | B4: LABOUR | E4: 5000
A5: 45818 | B5: OFFICE SUPPLY : EXERCISE BOOKS, BATTERY | E5: 3000
A6: 45818 | B6: REPAIR OF GEN | E6: 1000
A7: 45818 | B7: PLUMBING WORK | C7: EKWUEME | E7: 146500
A8: 16/10/2025 | B8: PLASTER | E8: 3000
A9: 16/10/2025 | B9: REFUND | E9: 1500
A10: 16/10/2025 | B10: REPAIR OF CHANGE OVER | E10: 3800
A11: 30/10/2025 | B11: TRANSPORT FOR CHINENYE | E11: 5000
A12: 30/10/2025 | B12: BANK CHARGES | E12: 365
A13: 30/10/2025 | B13: REFUND TO REV
A14: 30/10/2025 | B14: REPAIR OF THANK
B21: TOTAL | E21: =SUM(E2:E20) -> 178165
A26: 45698 | B26: FUEL | E26: 50000
A27: 16/10/2025 | B27: FUEL | E27: 51000
E30: =SUM(E26:E29) -> 101000

Sheet MEDICATIONS
A1: 45698 | B1: STORE PURCHASE:MEDICINE | C1: GRACE & MERCY | E1: 52000
A2: 45698 | B2: STORE PURCHASE:STRIP | C2: GRACE & MERCY | E2: 10000
A3: 45818 | B3: POVIDON | E3: 14000
A4: 45818 | B4: STORE PURCHASE:MEDICINE (LOCAL) | E4: 5000
A5: 30/10/2025 | B5: STORE PURCHASE:MEDICINE | E5: 64500
A6: 30/10/2025 | B6: STORE PURCHASE:MEDICINE | C6: ALVICE MEDICALS | D6: 624 | E6: 480000
A7: 30/10/2025 | B7: STORE PURCHASE:MEDICINE | C7: BLESSED MEKUS | E7: 162800
E18: =SUM(E1:E17) -> 788300
A21: 45698 | B21: WAYBILL | E21: 3000
A22: 30/10/2025 | B22: CARRIAGE | E22: 2000
A23: 30/10/2025 | B23: WAYBILL
E24: =SUM(E21:E23) -> 5000
E26: =E19+E24 -> 5000
C29: medi | D29: =E19 -> 0
C30: carriage | D30: =E24 -> 5000
D32: =D29+D30+D31 -> 5000

Sheet SUMMARY
A2: SUMMARY
B3: DEPOSITE INTO ACIU ACOUNT | F3: =REVENUE!H53 -> 1237900
B4: EXPENSES | F4: =REVENUE!H54 -> 1072465
B5: TOTAL | F5: =F3+F4 -> 2310365
B6: BAL B/D | F6: =REVENUE!J56 -> 0
B7: GRAND TOTAL | F7: =F5+F6 -> 2310365
A10: TOTAL CASH FOR THE MONTH OF OCTOMBER 2025
B12: TOTAL AMOUNT | F12: =REVENUE!H48 -> 1915635
B13: BAL. B/F
B14: TOTAL | F14: =F12+F13 -> 1915635
A17: OTHER POINTS TO NOTE
A18: WE STILL HAVE STOCK (MEDICATION) VALUED N1,450,000 AT COST PRICE AND DEBT OF N394,730.
A19: CASH RECEIVED IS N925,150
A20: CASH EARNED THROUGH INDEGENT,DELIVERY SUBSIDY, DEMENTIA,CHRONIC CARE AND BLOOM SCHOLARS N448,000
A21: TOTAT CASH IN BANK N1,237,700

Sheet LAB.
A2: STATEMENT OF FINANCIAL PERFORMANCE FOR THE MONTH ENDED 30/9/2025
B3: N | C3: N
A4: REVENUE (CASH) | C4: =REVENUE!E36 -> 308000
A5: Stock @ 1/10/2025 | B5: 340000
A6: Add PURCHASES | B6: 68000
A7: Add Carriage | B7: 5000
A8: Less STOCK AS AT 31/10/2025 | B8: 340000
A9: COST OF SALES | C9: =B5+B6+B7-B8 -> 73000
A10: GROSS PROFIT | C10: =C4-C9 -> 235000
A11: EXPENSES
A12: SALARIES | B12: 145000
A13: OFFICE SUPPLIES | B13: 5000
A14: POWER/LIGHTING | B14: 20000
A15: WAGES
A16: TRANSPORT | C16: =B12+B13+B14+B15+B16 -> 170000
A17: NET PROFIT/LOSS | C17: =C10-C16 -> 65000
A21: INDEGENT | C21: 17000
A22: CHRONIC HEALTH
A23: BLOOMS SCHOLARS
A24: PSYCHIATRICS
C25: =C21+C22+C23+C24 -> 17000
A26: ACTUAL NET PROFIT | C26: =C17+C25 -> 82000
